<?xml version='1.0' encoding='utf-8'?>
<mujoco>
  <option integrator="implicitfast" timestep="0.002" solver="Newton" />
  <compiler meshdir="meshes" autolimits="true" inertiafromgeom="true" angle="radian" />
  <default>
    <joint damping="10.0" armature="1.0" />
    <geom conaffinity="0" condim="3" friction="1 0.5 0.5" margin="0" />
  </default>
  <asset>
    <texture type="skybox" builtin="gradient" rgb1="0.3 0.5 0.7" rgb2="0 0 0" width="512" height="3072" />
    <texture type="2d" name="groundplane" builtin="checker" mark="edge" rgb1="0.2 0.3 0.4" rgb2="0.1 0.2 0.3" markrgb="0.8 0.8 0.8" width="300" height="300" />
    <material name="groundplane" texture="groundplane" texuniform="true" texrepeat="5 5" reflectance="0.1" />
    <mesh name="Compound" file="Compound.stl" scale="0.001 0.001 0.001" />
    <material name="Compound" rgba="1.0 1.0 1.0 1.0" shininess="0.8999999761581421" />
    <mesh name="Compound001" file="Compound001.stl" scale="0.001 0.001 0.001" />
    <material name="Compound001" rgba="0.3450980484485626 0.3686274588108063 0.8235294222831726 1.0" shininess="0.8999999761581421" />
    <mesh name="Solid" file="Solid.stl" scale="0.001 0.001 0.001" />
    <material name="Solid" rgba="1.0 1.0 1.0 1.0" shininess="0.8999999761581421" />
  </asset>
  <worldbody>
    <!--Lighting and floor-->
    <light diffuse=".8 .8 .8" pos="0 0 4" dir="0 0 -1" />
    <light diffuse=".6 .6 .6" pos="4 4 4" dir="-1 -1 -1" />
    <!--Part Meshes-->
    <geom name="floor" pos="0 0 -0.001" size="0 0 1" type="plane" material="groundplane" />
    <!--Assembly-->
    <body name="Compound" pos="0 0 0" quat="1.0 0.0 0.0 0.0">
      <geom type="mesh" name="Compound geom" mesh="Compound" material="Compound" contype="0" conaffinity="0" />
      <body name="Compound001" pos="0 0 0" quat="1.0 0.0 0.0 0.0">
        <geom type="mesh" name="Compound001 geom" mesh="Compound001" material="Compound001" contype="0" conaffinity="0" />
        <body name="Solid" pos="0 0 0" quat="1.0 0.0 0.0 0.0">
          <geom type="mesh" name="Solid geom" mesh="Solid" material="Solid" contype="0" conaffinity="0" />
        </body>
        <joint type="hinge" name="Revolute" pos="0.024621395828904734 -0.015898311411850077 0.037535451162087924" axis="-0.06948888167683064 0.260861617650757 -0.9628720121386507" />
      </body>
    </body>
  </worldbody>
  <contact />
  <equality />
  <tendon />
  <actuator>
    <position name="Revolute" joint="Revolute" kp="100" />
  </actuator>
  <sensor>
    <jointpos name="Revolute_pos" joint="Revolute" />
  </sensor>
</mujoco>