<?xml version='1.0' encoding='utf-8'?>
<mujoco>
  <option integrator="implicitfast" timestep="0.002" solver="Newton" />
  <compiler meshdir="meshes" autolimits="true" inertiafromgeom="true" angle="radian" />
  <default>
    <joint damping="10.0" armature="1.0" />
    <geom conaffinity="0" condim="3" friction="1 0.5 0.5" margin="0" />
  </default>
  <asset>
    <texture type="skybox" builtin="gradient" rgb1="0.3 0.5 0.7" rgb2="0 0 0" width="512" height="3072" />
    <texture type="2d" name="groundplane" builtin="checker" mark="edge" rgb1="0.2 0.3 0.4" rgb2="0.1 0.2 0.3" markrgb="0.8 0.8 0.8" width="300" height="300" />
    <material name="groundplane" texture="groundplane" texuniform="true" texrepeat="5 5" reflectance="0.1" />
    <mesh name="Compound" file="Compound.stl" scale="0.001 0.001 0.001" />
    <material name="Compound" rgba="1.0 1.0 1.0 1.0" shininess="0.8999999761581421" />
    <mesh name="Compound001" file="Compound001.stl" scale="0.001 0.001 0.001" />
    <material name="Compound001" rgba="0.3450980484485626 0.3686274588108063 0.8235294222831726 1.0" shininess="0.8999999761581421" />
    <mesh name="Solid" file="Solid.stl" scale="0.001 0.001 0.001" />
    <material name="Solid" rgba="1.0 1.0 1.0 1.0" shininess="0.8999999761581421" />
    <mesh name="Part__Feature" file="Part__Feature.stl" scale="0.001 0.001 0.001" />
    <material name="Part__Feature" rgba="1.0 1.0 1.0 1.0" shininess="0.8999999761581421" />
    <mesh name="Compound002" file="Compound002.stl" scale="0.001 0.001 0.001" />
    <material name="Compound002" rgba="0.3450980484485626 0.3686274588108063 0.8235294222831726 1.0" shininess="0.8999999761581421" />
    <mesh name="Part__Feature003" file="Part__Feature003.stl" scale="0.001 0.001 0.001" />
    <material name="Part__Feature003" rgba="1.0 1.0 1.0 1.0" shininess="0.8999999761581421" />
    <mesh name="Part__Feature004" file="Part__Feature004.stl" scale="0.001 0.001 0.001" />
    <material name="Part__Feature004" rgba="1.0 1.0 1.0 1.0" shininess="0.8999999761581421" />
    <mesh name="Compound003" file="Compound003.stl" scale="0.001 0.001 0.001" />
    <material name="Compound003" rgba="0.3450980484485626 0.3686274588108063 0.8235294222831726 1.0" shininess="0.8999999761581421" />
    <mesh name="Solid001" file="Solid001.stl" scale="0.001 0.001 0.001" />
    <material name="Solid001" rgba="1.0 1.0 1.0 1.0" shininess="0.8999999761581421" />
    <mesh name="Part__Feature005" file="Part__Feature005.stl" scale="0.001 0.001 0.001" />
    <material name="Part__Feature005" rgba="1.0 1.0 1.0 1.0" shininess="0.8999999761581421" />
    <mesh name="Part__Feature006" file="Part__Feature006.stl" scale="0.001 0.001 0.001" />
    <material name="Part__Feature006" rgba="0.6274510025978088 0.6274510025978088 0.6274510025978088 1.0" shininess="0.8999999761581421" />
    <mesh name="Compound004" file="Compound004.stl" scale="0.001 0.001 0.001" />
    <material name="Compound004" rgba="0.3450980484485626 0.3686274588108063 0.8235294222831726 1.0" shininess="0.8999999761581421" />
    <mesh name="Solid002" file="Solid002.stl" scale="0.001 0.001 0.001" />
    <material name="Solid002" rgba="1.0 1.0 1.0 1.0" shininess="0.8999999761581421" />
    <mesh name="Part__Feature007" file="Part__Feature007.stl" scale="0.001 0.001 0.001" />
    <material name="Part__Feature007" rgba="1.0 1.0 1.0 1.0" shininess="0.8999999761581421" />
    <mesh name="Compound005" file="Compound005.stl" scale="0.001 0.001 0.001" />
    <material name="Compound005" rgba="0.3450980484485626 0.3686274588108063 0.8235294222831726 1.0" shininess="0.8999999761581421" />
    <mesh name="Solid003" file="Solid003.stl" scale="0.001 0.001 0.001" />
    <material name="Solid003" rgba="1.0 1.0 1.0 1.0" shininess="0.8999999761581421" />
    <mesh name="Part__Feature008" file="Part__Feature008.stl" scale="0.001 0.001 0.001" />
    <material name="Part__Feature008" rgba="1.0 1.0 1.0 1.0" shininess="0.8999999761581421" />
    <mesh name="Compound006" file="Compound006.stl" scale="0.001 0.001 0.001" />
    <material name="Compound006" rgba="0.3450980484485626 0.3686274588108063 0.8235294222831726 1.0" shininess="0.8999999761581421" />
    <mesh name="Part__Feature009" file="Part__Feature009.stl" scale="0.001 0.001 0.001" />
    <material name="Part__Feature009" rgba="1.0 1.0 1.0 1.0" shininess="0.8999999761581421" />
    <mesh name="Part__Feature010" file="Part__Feature010.stl" scale="0.001 0.001 0.001" />
    <material name="Part__Feature010" rgba="0.6274510025978088 0.6274510025978088 0.6274510025978088 1.0" shininess="0.8999999761581421" />
    <mesh name="Compound007" file="Compound007.stl" scale="0.001 0.001 0.001" />
    <material name="Compound007" rgba="0.3450980484485626 0.3686274588108063 0.8235294222831726 1.0" shininess="0.8999999761581421" />
    <mesh name="Solid004" file="Solid004.stl" scale="0.001 0.001 0.001" />
    <material name="Solid004" rgba="1.0 1.0 1.0 1.0" shininess="0.8999999761581421" />
    <mesh name="Part__Feature011" file="Part__Feature011.stl" scale="0.001 0.001 0.001" />
    <material name="Part__Feature011" rgba="1.0 1.0 1.0 1.0" shininess="0.8999999761581421" />
    <mesh name="Compound008" file="Compound008.stl" scale="0.001 0.001 0.001" />
    <material name="Compound008" rgba="0.3450980484485626 0.3686274588108063 0.8235294222831726 1.0" shininess="0.8999999761581421" />
    <mesh name="Solid005" file="Solid005.stl" scale="0.001 0.001 0.001" />
    <material name="Solid005" rgba="1.0 1.0 1.0 1.0" shininess="0.8999999761581421" />
    <mesh name="Part__Feature012" file="Part__Feature012.stl" scale="0.001 0.001 0.001" />
    <material name="Part__Feature012" rgba="1.0 1.0 1.0 1.0" shininess="0.8999999761581421" />
    <mesh name="Compound009" file="Compound009.stl" scale="0.001 0.001 0.001" />
    <material name="Compound009" rgba="0.3450980484485626 0.3686274588108063 0.8235294222831726 1.0" shininess="0.8999999761581421" />
    <mesh name="Solid006" file="Solid006.stl" scale="0.001 0.001 0.001" />
    <material name="Solid006" rgba="1.0 1.0 1.0 1.0" shininess="0.8999999761581421" />
    <mesh name="Part__Feature013" file="Part__Feature013.stl" scale="0.001 0.001 0.001" />
    <material name="Part__Feature013" rgba="1.0 1.0 1.0 1.0" shininess="0.8999999761581421" />
    <mesh name="Compound010" file="Compound010.stl" scale="0.001 0.001 0.001" />
    <material name="Compound010" rgba="0.3450980484485626 0.3686274588108063 0.8235294222831726 1.0" shininess="0.8999999761581421" />
    <mesh name="Solid008" file="Solid008.stl" scale="0.001 0.001 0.001" />
    <material name="Solid008" rgba="1.0 1.0 1.0 1.0" shininess="0.8999999761581421" />
    <mesh name="Part__Feature014" file="Part__Feature014.stl" scale="0.001 0.001 0.001" />
    <material name="Part__Feature014" rgba="1.0 1.0 1.0 1.0" shininess="0.8999999761581421" />
    <mesh name="Compound011" file="Compound011.stl" scale="0.001 0.001 0.001" />
    <material name="Compound011" rgba="0.3450980484485626 0.3686274588108063 0.8235294222831726 1.0" shininess="0.8999999761581421" />
    <mesh name="Solid009" file="Solid009.stl" scale="0.001 0.001 0.001" />
    <material name="Solid009" rgba="1.0 1.0 1.0 1.0" shininess="0.8999999761581421" />
    <mesh name="Part__Feature015" file="Part__Feature015.stl" scale="0.001 0.001 0.001" />
    <material name="Part__Feature015" rgba="1.0 1.0 1.0 1.0" shininess="0.8999999761581421" />
    <mesh name="Compound012" file="Compound012.stl" scale="0.001 0.001 0.001" />
    <material name="Compound012" rgba="0.3450980484485626 0.3686274588108063 0.8235294222831726 1.0" shininess="0.8999999761581421" />
    <mesh name="Solid010" file="Solid010.stl" scale="0.001 0.001 0.001" />
    <material name="Solid010" rgba="1.0 1.0 1.0 1.0" shininess="0.8999999761581421" />
    <mesh name="Part__Feature016" file="Part__Feature016.stl" scale="0.001 0.001 0.001" />
    <material name="Part__Feature016" rgba="1.0 1.0 1.0 1.0" shininess="0.8999999761581421" />
    <mesh name="Compound013" file="Compound013.stl" scale="0.001 0.001 0.001" />
    <material name="Compound013" rgba="0.3450980484485626 0.3686274588108063 0.8235294222831726 1.0" shininess="0.8999999761581421" />
    <mesh name="Solid011" file="Solid011.stl" scale="0.001 0.001 0.001" />
    <material name="Solid011" rgba="1.0 1.0 1.0 1.0" shininess="0.8999999761581421" />
    <mesh name="Part__Feature017" file="Part__Feature017.stl" scale="0.001 0.001 0.001" />
    <material name="Part__Feature017" rgba="1.0 1.0 1.0 1.0" shininess="0.8999999761581421" />
    <mesh name="Compound014" file="Compound014.stl" scale="0.001 0.001 0.001" />
    <material name="Compound014" rgba="0.3450980484485626 0.3686274588108063 0.8235294222831726 1.0" shininess="0.8999999761581421" />
    <mesh name="Solid012" file="Solid012.stl" scale="0.001 0.001 0.001" />
    <material name="Solid012" rgba="1.0 1.0 1.0 1.0" shininess="0.8999999761581421" />
    <mesh name="Part__Feature018" file="Part__Feature018.stl" scale="0.001 0.001 0.001" />
    <material name="Part__Feature018" rgba="1.0 1.0 1.0 1.0" shininess="0.8999999761581421" />
    <mesh name="Compound015" file="Compound015.stl" scale="0.001 0.001 0.001" />
    <material name="Compound015" rgba="0.3450980484485626 0.3686274588108063 0.8235294222831726 1.0" shininess="0.8999999761581421" />
    <mesh name="Solid013" file="Solid013.stl" scale="0.001 0.001 0.001" />
    <material name="Solid013" rgba="1.0 1.0 1.0 1.0" shininess="0.8999999761581421" />
    <mesh name="Solid014" file="Solid014.stl" scale="0.001 0.001 0.001" />
    <material name="Solid014" rgba="1.0 1.0 1.0 1.0" shininess="0.8999999761581421" />
    <mesh name="Part__Feature019" file="Part__Feature019.stl" scale="0.001 0.001 0.001" />
    <material name="Part__Feature019" rgba="1.0 1.0 1.0 1.0" shininess="0.8999999761581421" />
    <mesh name="Compound016" file="Compound016.stl" scale="0.001 0.001 0.001" />
    <material name="Compound016" rgba="0.3450980484485626 0.3686274588108063 0.8235294222831726 1.0" shininess="0.8999999761581421" />
    <mesh name="Part__Feature020" file="Part__Feature020.stl" scale="0.001 0.001 0.001" />
    <material name="Part__Feature020" rgba="1.0 1.0 1.0 1.0" shininess="0.8999999761581421" />
    <mesh name="Compound017" file="Compound017.stl" scale="0.001 0.001 0.001" />
    <material name="Compound017" rgba="0.3450980484485626 0.3686274588108063 0.8235294222831726 1.0" shininess="0.8999999761581421" />
    <mesh name="Solid015" file="Solid015.stl" scale="0.001 0.001 0.001" />
    <material name="Solid015" rgba="1.0 1.0 1.0 1.0" shininess="0.8999999761581421" />
    <mesh name="Part__Feature021" file="Part__Feature021.stl" scale="0.001 0.001 0.001" />
    <material name="Part__Feature021" rgba="1.0 1.0 1.0 1.0" shininess="0.8999999761581421" />
    <mesh name="Compound018" file="Compound018.stl" scale="0.001 0.001 0.001" />
    <material name="Compound018" rgba="0.3450980484485626 0.3686274588108063 0.8235294222831726 1.0" shininess="0.8999999761581421" />
    <mesh name="Solid016" file="Solid016.stl" scale="0.001 0.001 0.001" />
    <material name="Solid016" rgba="1.0 1.0 1.0 1.0" shininess="0.8999999761581421" />
    <mesh name="Part__Feature022" file="Part__Feature022.stl" scale="0.001 0.001 0.001" />
    <material name="Part__Feature022" rgba="1.0 1.0 1.0 1.0" shininess="0.8999999761581421" />
  </asset>
  <worldbody>
    <!--Lighting and floor-->
    <light diffuse=".8 .8 .8" pos="0 0 4" dir="0 0 -1" />
    <light diffuse=".6 .6 .6" pos="4 4 4" dir="-1 -1 -1" />
    <!--Part Meshes-->
    <geom name="floor" pos="0 0 -0.015288718024182791" size="0 0 1" type="plane" material="groundplane" />
    <!--Assembly-->
    <body name="Compound" pos="0 0 0" quat="1.0 0.0 0.0 0.0">
      <geom type="mesh" name="Compound geom" mesh="Compound" material="Compound" contype="0" conaffinity="0" />
      <body name="Compound001" pos="0 0 0" quat="1.0 0.0 0.0 0.0">
        <geom type="mesh" name="Compound001 geom" mesh="Compound001" material="Compound001" contype="0" conaffinity="0" />
        <body name="Solid" pos="0 0 0" quat="1.0 0.0 0.0 0.0">
          <geom type="mesh" name="Solid geom" mesh="Solid" material="Solid" contype="0" conaffinity="0" />
        </body>
        <body name="Part__Feature" pos="0 0 0" quat="1.0 0.0 0.0 0.0">
          <geom type="mesh" name="Part__Feature geom" mesh="Part__Feature" material="Part__Feature" contype="0" conaffinity="0" />
          <body name="Compound002" pos="0 0 0" quat="1.0 0.0 0.0 0.0">
            <geom type="mesh" name="Compound002 geom" mesh="Compound002" material="Compound002" contype="0" conaffinity="0" />
            <body name="Part__Feature003" pos="0 0 0" quat="1.0 0.0 0.0 0.0">
              <geom type="mesh" name="Part__Feature003 geom" mesh="Part__Feature003" material="Part__Feature003" contype="0" conaffinity="0" />
            </body>
            <body name="Part__Feature004" pos="0 0 0" quat="1.0 0.0 0.0 0.0">
              <geom type="mesh" name="Part__Feature004 geom" mesh="Part__Feature004" material="Part__Feature004" contype="0" conaffinity="0" />
              <body name="Compound003" pos="0 0 0" quat="1.0 0.0 0.0 0.0">
                <geom type="mesh" name="Compound003 geom" mesh="Compound003" material="Compound003" contype="0" conaffinity="0" />
                <body name="Solid001" pos="0 0 0" quat="1.0 0.0 0.0 0.0">
                  <geom type="mesh" name="Solid001 geom" mesh="Solid001" material="Solid001" contype="0" conaffinity="0" />
                </body>
                <body name="Part__Feature005" pos="0 0 0" quat="1.0 0.0 0.0 0.0">
                  <geom type="mesh" name="Part__Feature005 geom" mesh="Part__Feature005" material="Part__Feature005" contype="0" conaffinity="0" />
                  <body name="Part__Feature006" pos="0 0 0" quat="1.0 0.0 0.0 0.0">
                    <geom type="mesh" name="Part__Feature006 geom" mesh="Part__Feature006" material="Part__Feature006" contype="0" conaffinity="0" />
                  </body>
                </body>
                <joint type="hinge" name="Revolute002" pos="0.022370026219401967 0.03101228346406784 0.07694119331606376" axis="-0.9563412316668667 0.28710772052817735 0.054594921256599566" />
              </body>
            </body>
            <joint type="hinge" name="Revolute001" pos="0.019688740755565017 0.034155217190347385 0.03432579380070507" axis="-0.9563412316668667 0.28710772052817723 0.05459492125660019" />
          </body>
        </body>
        <joint type="hinge" name="Revolute" pos="0.02166900765210381 -0.014010170976901524 0.043162983722660524" axis="-0.004768051882588317 -0.2021104892957568 0.9793511197715938" />
      </body>
      <body name="Compound004" pos="0 0 0" quat="1.0 0.0 0.0 0.0">
        <geom type="mesh" name="Compound004 geom" mesh="Compound004" material="Compound004" contype="0" conaffinity="0" />
        <body name="Solid002" pos="0 0 0" quat="1.0 0.0 0.0 0.0">
          <geom type="mesh" name="Solid002 geom" mesh="Solid002" material="Solid002" contype="0" conaffinity="0" />
        </body>
        <body name="Part__Feature007" pos="0 0 0" quat="1.0 0.0 0.0 0.0">
          <geom type="mesh" name="Part__Feature007 geom" mesh="Part__Feature007" material="Part__Feature007" contype="0" conaffinity="0" />
          <body name="Compound005" pos="0 0 0" quat="1.0 0.0 0.0 0.0">
            <geom type="mesh" name="Compound005 geom" mesh="Compound005" material="Compound005" contype="0" conaffinity="0" />
            <body name="Solid003" pos="0 0 0" quat="1.0 0.0 0.0 0.0">
              <geom type="mesh" name="Solid003 geom" mesh="Solid003" material="Solid003" contype="0" conaffinity="0" />
            </body>
            <body name="Part__Feature008" pos="0 0 0" quat="1.0 0.0 0.0 0.0">
              <geom type="mesh" name="Part__Feature008 geom" mesh="Part__Feature008" material="Part__Feature008" contype="0" conaffinity="0" />
              <body name="Compound006" pos="0 0 0" quat="1.0 0.0 0.0 0.0">
                <geom type="mesh" name="Compound006 geom" mesh="Compound006" material="Compound006" contype="0" conaffinity="0" />
                <body name="Part__Feature009" pos="0 0 0" quat="1.0 0.0 0.0 0.0">
                  <geom type="mesh" name="Part__Feature009 geom" mesh="Part__Feature009" material="Part__Feature009" contype="0" conaffinity="0" />
                  <body name="Part__Feature010" pos="0 0 0" quat="1.0 0.0 0.0 0.0">
                    <geom type="mesh" name="Part__Feature010 geom" mesh="Part__Feature010" material="Part__Feature010" contype="0" conaffinity="0" />
                  </body>
                </body>
                <body name="Solid014" pos="0 0 0" quat="1.0 0.0 0.0 0.0">
                  <geom type="mesh" name="Solid014 geom" mesh="Solid014" material="Solid014" contype="0" conaffinity="0" />
                </body>
                <joint type="hinge" name="Revolute005" pos="-0.020726435785413576 -0.1271141544712626 0.03461721491321861" axis="0.7157408853639673 -0.6846348287576869 -0.13780470336798203" />
              </body>
            </body>
            <joint type="hinge" name="Revolute004" pos="-0.0016593491372964096 -0.10286894182863249 0.004922847254235819" axis="0.7157408853639683 -0.6846348287576854 -0.1378047033679845" />
          </body>
        </body>
        <joint type="hinge" name="Revolute003" pos="0.017244024622226833 -0.06577264093294008 0.02939587159459925" axis="0.0047680518825883285 0.2021104892957568 -0.9793511197715938" />
      </body>
      <body name="Compound007" pos="0 0 0" quat="1.0 0.0 0.0 0.0">
        <geom type="mesh" name="Compound007 geom" mesh="Compound007" material="Compound007" contype="0" conaffinity="0" />
        <body name="Solid004" pos="0 0 0" quat="1.0 0.0 0.0 0.0">
          <geom type="mesh" name="Solid004 geom" mesh="Solid004" material="Solid004" contype="0" conaffinity="0" />
        </body>
        <body name="Part__Feature011" pos="0 0 0" quat="1.0 0.0 0.0 0.0">
          <geom type="mesh" name="Part__Feature011 geom" mesh="Part__Feature011" material="Part__Feature011" contype="0" conaffinity="0" />
          <body name="Compound008" pos="0 0 0" quat="1.0 0.0 0.0 0.0">
            <geom type="mesh" name="Compound008 geom" mesh="Compound008" material="Compound008" contype="0" conaffinity="0" />
            <body name="Solid005" pos="0 0 0" quat="1.0 0.0 0.0 0.0">
              <geom type="mesh" name="Solid005 geom" mesh="Solid005" material="Solid005" contype="0" conaffinity="0" />
            </body>
            <body name="Part__Feature012" pos="0 0 0" quat="1.0 0.0 0.0 0.0">
              <geom type="mesh" name="Part__Feature012 geom" mesh="Part__Feature012" material="Part__Feature012" contype="0" conaffinity="0" />
              <body name="Compound009" pos="0 0 0" quat="1.0 0.0 0.0 0.0">
                <geom type="mesh" name="Compound009 geom" mesh="Compound009" material="Compound009" contype="0" conaffinity="0" />
                <body name="Solid006" pos="0 0 0" quat="1.0 0.0 0.0 0.0">
                  <geom type="mesh" name="Solid006 geom" mesh="Solid006" material="Solid006" contype="0" conaffinity="0" />
                </body>
                <body name="Part__Feature013" pos="0 0 0" quat="1.0 0.0 0.0 0.0">
                  <geom type="mesh" name="Part__Feature013 geom" mesh="Part__Feature013" material="Part__Feature013" contype="0" conaffinity="0" />
                </body>
                <joint type="hinge" name="Revolute008" pos="0.06309686698627572 0.06836539163590696 0.047819800562966454" axis="-0.9978083728613792 0.0655981248055639 0.008679692950813" />
              </body>
            </body>
            <joint type="hinge" name="Revolute007" pos="0.059207555249631186 0.02862989511987556 0.0323568393058316" axis="-0.9978083728613794 0.0655981248055646 0.008679692950812945" />
          </body>
        </body>
        <joint type="hinge" name="Revolute006" pos="0.07151134601218004 -0.017502982012691997 0.039621574699694635" axis="-0.004768051882588331 -0.2021104892957568 0.9793511197715938" />
      </body>
      <body name="Compound010" pos="0 0 0" quat="1.0 0.0 0.0 0.0">
        <geom type="mesh" name="Compound010 geom" mesh="Compound010" material="Compound010" contype="0" conaffinity="0" />
        <body name="Solid008" pos="0 0 0" quat="1.0 0.0 0.0 0.0">
          <geom type="mesh" name="Solid008 geom" mesh="Solid008" material="Solid008" contype="0" conaffinity="0" />
        </body>
        <body name="Part__Feature014" pos="0 0 0" quat="1.0 0.0 0.0 0.0">
          <geom type="mesh" name="Part__Feature014 geom" mesh="Part__Feature014" material="Part__Feature014" contype="0" conaffinity="0" />
          <body name="Compound011" pos="0 0 0" quat="1.0 0.0 0.0 0.0">
            <geom type="mesh" name="Compound011 geom" mesh="Compound011" material="Compound011" contype="0" conaffinity="0" />
            <body name="Solid009" pos="0 0 0" quat="1.0 0.0 0.0 0.0">
              <geom type="mesh" name="Solid009 geom" mesh="Solid009" material="Solid009" contype="0" conaffinity="0" />
            </body>
            <body name="Part__Feature015" pos="0 0 0" quat="1.0 0.0 0.0 0.0">
              <geom type="mesh" name="Part__Feature015 geom" mesh="Part__Feature015" material="Part__Feature015" contype="0" conaffinity="0" />
              <body name="Compound012" pos="0 0 0" quat="1.0 0.0 0.0 0.0">
                <geom type="mesh" name="Compound012 geom" mesh="Compound012" material="Compound012" contype="0" conaffinity="0" />
                <body name="Solid010" pos="0 0 0" quat="1.0 0.0 0.0 0.0">
                  <geom type="mesh" name="Solid010 geom" mesh="Solid010" material="Solid010" contype="0" conaffinity="0" />
                </body>
                <body name="Part__Feature016" pos="0 0 0" quat="1.0 0.0 0.0 0.0">
                  <geom type="mesh" name="Part__Feature016 geom" mesh="Part__Feature016" material="Part__Feature016" contype="0" conaffinity="0" />
                </body>
                <joint type="hinge" name="Revolute012" pos="0.18828007195887456 0.034376402663642565 0.018073225848690692" axis="-0.4610401765185782 0.8695073888321558 0.17719722458888693" />
              </body>
            </body>
            <joint type="hinge" name="Revolute011" pos="0.15237051279040476 0.014248641924215828 0.029842525230665728" axis="-0.461040176518578 0.8695073888321561 0.17719722458888662" />
          </body>
        </body>
        <joint type="hinge" name="Revolute010" pos="0.1213393802166081 -0.0216021245163697 0.03901821903604354" axis="-0.004768051882588352 -0.20211048929575684 0.979351119771594" />
      </body>
      <body name="Compound013" pos="0 0 0" quat="1.0 0.0 0.0 0.0">
        <geom type="mesh" name="Compound013 geom" mesh="Compound013" material="Compound013" contype="0" conaffinity="0" />
        <body name="Solid011" pos="0 0 0" quat="1.0 0.0 0.0 0.0">
          <geom type="mesh" name="Solid011 geom" mesh="Solid011" material="Solid011" contype="0" conaffinity="0" />
        </body>
        <body name="Part__Feature017" pos="0 0 0" quat="1.0 0.0 0.0 0.0">
          <geom type="mesh" name="Part__Feature017 geom" mesh="Part__Feature017" material="Part__Feature017" contype="0" conaffinity="0" />
          <body name="Compound014" pos="0 0 0" quat="1.0 0.0 0.0 0.0">
            <geom type="mesh" name="Compound014 geom" mesh="Compound014" material="Compound014" contype="0" conaffinity="0" />
            <body name="Solid012" pos="0 0 0" quat="1.0 0.0 0.0 0.0">
              <geom type="mesh" name="Solid012 geom" mesh="Solid012" material="Solid012" contype="0" conaffinity="0" />
            </body>
            <body name="Part__Feature018" pos="0 0 0" quat="1.0 0.0 0.0 0.0">
              <geom type="mesh" name="Part__Feature018 geom" mesh="Part__Feature018" material="Part__Feature018" contype="0" conaffinity="0" />
              <body name="Compound015" pos="0 0 0" quat="1.0 0.0 0.0 0.0">
                <geom type="mesh" name="Compound015 geom" mesh="Compound015" material="Compound015" contype="0" conaffinity="0" />
                <body name="Solid013" pos="0 0 0" quat="1.0 0.0 0.0 0.0">
                  <geom type="mesh" name="Solid013 geom" mesh="Solid013" material="Solid013" contype="0" conaffinity="0" />
                </body>
                <body name="Part__Feature019" pos="0 0 0" quat="1.0 0.0 0.0 0.0">
                  <geom type="mesh" name="Part__Feature019 geom" mesh="Part__Feature019" material="Part__Feature019" contype="0" conaffinity="0" />
                </body>
                <joint type="hinge" name="Revolute015" pos="0.06336281387225545 -0.14704731086640388 -0.015512788195393116" axis="0.9774298612086043 -0.20779184520453006 -0.03812368665574255" />
              </body>
            </body>
            <joint type="hinge" name="Revolute014" pos="0.0730065578264591 -0.11069035418654607 0.0036722451610215583" axis="0.9774298612086048 -0.20779184520452743 -0.038123686655741285" />
          </body>
        </body>
        <joint type="hinge" name="Revolute013" pos="0.06707205882665529 -0.0698717834366178 0.028792515930948143" axis="-0.004768051882588303 -0.2021104892957568 0.9793511197715938" />
      </body>
      <body name="Compound016" pos="0 0 0" quat="1.0 0.0 0.0 0.0">
        <geom type="mesh" name="Compound016 geom" mesh="Compound016" material="Compound016" contype="0" conaffinity="0" />
        <body name="Part__Feature020" pos="0 0 0" quat="1.0 0.0 0.0 0.0">
          <geom type="mesh" name="Part__Feature020 geom" mesh="Part__Feature020" material="Part__Feature020" contype="0" conaffinity="0" />
          <body name="Compound017" pos="0 0 0" quat="1.0 0.0 0.0 0.0">
            <geom type="mesh" name="Compound017 geom" mesh="Compound017" material="Compound017" contype="0" conaffinity="0" />
            <body name="Solid015" pos="0 0 0" quat="1.0 0.0 0.0 0.0">
              <geom type="mesh" name="Solid015 geom" mesh="Solid015" material="Solid015" contype="0" conaffinity="0" />
            </body>
            <body name="Part__Feature021" pos="0 0 0" quat="1.0 0.0 0.0 0.0">
              <geom type="mesh" name="Part__Feature021 geom" mesh="Part__Feature021" material="Part__Feature021" contype="0" conaffinity="0" />
              <body name="Compound018" pos="0 0 0" quat="1.0 0.0 0.0 0.0">
                <geom type="mesh" name="Compound018 geom" mesh="Compound018" material="Compound018" contype="0" conaffinity="0" />
                <body name="Solid016" pos="0 0 0" quat="1.0 0.0 0.0 0.0">
                  <geom type="mesh" name="Solid016 geom" mesh="Solid016" material="Solid016" contype="0" conaffinity="0" />
                </body>
                <body name="Part__Feature022" pos="0 0 0" quat="1.0 0.0 0.0 0.0">
                  <geom type="mesh" name="Part__Feature022 geom" mesh="Part__Feature022" material="Part__Feature022" contype="0" conaffinity="0" />
                </body>
                <joint type="hinge" name="Revolute018" pos="0.13975356752487553 -0.15335316107157448 0.007465694170866786" axis="0.9944561333227822 0.10191905081095709 0.025874813593426707" />
              </body>
            </body>
            <joint type="hinge" name="Revolute017" pos="0.1366295930054685 -0.11079624007927819 0.003960147300896995" axis="0.9944561333227818 0.1019190508109607 0.0258748135934265" />
          </body>
        </body>
        <joint type="hinge" name="Revolute016" pos="0.11690009303108337 -0.07397092594029553 0.028189160267297043" axis="-0.004768051882588359 -0.20211048929575687 0.9793511197715938" />
      </body>
    </body>
  </worldbody>
  <contact />
  <equality />
  <tendon />
  <actuator>
    <position name="Revolute002" joint="Revolute002" kp="100" />
    <position name="Revolute001" joint="Revolute001" kp="100" />
    <position name="Revolute" joint="Revolute" kp="100" />
    <position name="Revolute005" joint="Revolute005" kp="100" />
    <position name="Revolute004" joint="Revolute004" kp="100" />
    <position name="Revolute003" joint="Revolute003" kp="100" />
    <position name="Revolute008" joint="Revolute008" kp="100" />
    <position name="Revolute007" joint="Revolute007" kp="100" />
    <position name="Revolute006" joint="Revolute006" kp="100" />
    <position name="Revolute012" joint="Revolute012" kp="100" />
    <position name="Revolute011" joint="Revolute011" kp="100" />
    <position name="Revolute010" joint="Revolute010" kp="100" />
    <position name="Revolute015" joint="Revolute015" kp="100" />
    <position name="Revolute014" joint="Revolute014" kp="100" />
    <position name="Revolute013" joint="Revolute013" kp="100" />
    <position name="Revolute018" joint="Revolute018" kp="100" />
    <position name="Revolute017" joint="Revolute017" kp="100" />
    <position name="Revolute016" joint="Revolute016" kp="100" />
  </actuator>
  <sensor>
    <jointpos name="Revolute002_pos" joint="Revolute002" />
    <jointpos name="Revolute001_pos" joint="Revolute001" />
    <jointpos name="Revolute_pos" joint="Revolute" />
    <jointpos name="Revolute005_pos" joint="Revolute005" />
    <jointpos name="Revolute004_pos" joint="Revolute004" />
    <jointpos name="Revolute003_pos" joint="Revolute003" />
    <jointpos name="Revolute008_pos" joint="Revolute008" />
    <jointpos name="Revolute007_pos" joint="Revolute007" />
    <jointpos name="Revolute006_pos" joint="Revolute006" />
    <jointpos name="Revolute012_pos" joint="Revolute012" />
    <jointpos name="Revolute011_pos" joint="Revolute011" />
    <jointpos name="Revolute010_pos" joint="Revolute010" />
    <jointpos name="Revolute015_pos" joint="Revolute015" />
    <jointpos name="Revolute014_pos" joint="Revolute014" />
    <jointpos name="Revolute013_pos" joint="Revolute013" />
    <jointpos name="Revolute018_pos" joint="Revolute018" />
    <jointpos name="Revolute017_pos" joint="Revolute017" />
    <jointpos name="Revolute016_pos" joint="Revolute016" />
  </sensor>
</mujoco>