<?xml version='1.0' encoding='utf-8'?>
<mujoco>
  <option integrator="implicitfast" timestep="0.002" solver="Newton" />
  <compiler meshdir="meshes" autolimits="true" inertiafromgeom="true" angle="radian" />
  <default>
    <joint damping="10.0" armature="1.0" />
    <geom conaffinity="0" condim="3" friction="1 0.5 0.5" margin="0" />
  </default>
  <asset>
    <texture type="skybox" builtin="gradient" rgb1="0.3 0.5 0.7" rgb2="0 0 0" width="512" height="3072" />
    <texture type="2d" name="groundplane" builtin="checker" mark="edge" rgb1="0.2 0.3 0.4" rgb2="0.1 0.2 0.3" markrgb="0.8 0.8 0.8" width="300" height="300" />
    <material name="groundplane" texture="groundplane" texuniform="true" texrepeat="5 5" reflectance="0.1" />
    <mesh name="Compound" file="Compound.stl" scale="0.001 0.001 0.001" />
    <material name="Compound" rgba="1.0 1.0 1.0 1.0" shininess="0.8999999761581421" />
    <mesh name="Compound001" file="Compound001.stl" scale="0.001 0.001 0.001" />
    <material name="Compound001" rgba="0.3450980484485626 0.3686274588108063 0.8235294222831726 1.0" shininess="0.8999999761581421" />
    <mesh name="Solid" file="Solid.stl" scale="0.001 0.001 0.001" />
    <material name="Solid" rgba="1.0 1.0 1.0 1.0" shininess="0.8999999761581421" />
    <mesh name="Part__Feature" file="Part__Feature.stl" scale="0.001 0.001 0.001" />
    <material name="Part__Feature" rgba="1.0 1.0 1.0 1.0" shininess="0.8999999761581421" />
    <mesh name="Compound002" file="Compound002.stl" scale="0.001 0.001 0.001" />
    <material name="Compound002" rgba="0.3450980484485626 0.3686274588108063 0.8235294222831726 1.0" shininess="0.8999999761581421" />
    <mesh name="Part__Feature003" file="Part__Feature003.stl" scale="0.001 0.001 0.001" />
    <material name="Part__Feature003" rgba="1.0 1.0 1.0 1.0" shininess="0.8999999761581421" />
    <mesh name="Part__Feature004" file="Part__Feature004.stl" scale="0.001 0.001 0.001" />
    <material name="Part__Feature004" rgba="1.0 1.0 1.0 1.0" shininess="0.8999999761581421" />
    <mesh name="Compound003" file="Compound003.stl" scale="0.001 0.001 0.001" />
    <material name="Compound003" rgba="0.3450980484485626 0.3686274588108063 0.8235294222831726 1.0" shininess="0.8999999761581421" />
    <mesh name="Solid001" file="Solid001.stl" scale="0.001 0.001 0.001" />
    <material name="Solid001" rgba="1.0 1.0 1.0 1.0" shininess="0.8999999761581421" />
    <mesh name="Part__Feature005" file="Part__Feature005.stl" scale="0.001 0.001 0.001" />
    <material name="Part__Feature005" rgba="1.0 1.0 1.0 1.0" shininess="0.8999999761581421" />
    <mesh name="Part__Feature006" file="Part__Feature006.stl" scale="0.001 0.001 0.001" />
    <material name="Part__Feature006" rgba="0.6274510025978088 0.6274510025978088 0.6274510025978088 1.0" shininess="0.8999999761581421" />
    <mesh name="Compound004" file="Compound004.stl" scale="0.001 0.001 0.001" />
    <material name="Compound004" rgba="0.3450980484485626 0.3686274588108063 0.8235294222831726 1.0" shininess="0.8999999761581421" />
    <mesh name="Solid002" file="Solid002.stl" scale="0.001 0.001 0.001" />
    <material name="Solid002" rgba="1.0 1.0 1.0 1.0" shininess="0.8999999761581421" />
    <mesh name="Part__Feature007" file="Part__Feature007.stl" scale="0.001 0.001 0.001" />
    <material name="Part__Feature007" rgba="1.0 1.0 1.0 1.0" shininess="0.8999999761581421" />
    <mesh name="Compound005" file="Compound005.stl" scale="0.001 0.001 0.001" />
    <material name="Compound005" rgba="0.3450980484485626 0.3686274588108063 0.8235294222831726 1.0" shininess="0.8999999761581421" />
    <mesh name="Solid003" file="Solid003.stl" scale="0.001 0.001 0.001" />
    <material name="Solid003" rgba="1.0 1.0 1.0 1.0" shininess="0.8999999761581421" />
    <mesh name="Part__Feature008" file="Part__Feature008.stl" scale="0.001 0.001 0.001" />
    <material name="Part__Feature008" rgba="1.0 1.0 1.0 1.0" shininess="0.8999999761581421" />
    <mesh name="Compound006" file="Compound006.stl" scale="0.001 0.001 0.001" />
    <material name="Compound006" rgba="0.3450980484485626 0.3686274588108063 0.8235294222831726 1.0" shininess="0.8999999761581421" />
    <mesh name="Part__Feature009" file="Part__Feature009.stl" scale="0.001 0.001 0.001" />
    <material name="Part__Feature009" rgba="1.0 1.0 1.0 1.0" shininess="0.8999999761581421" />
    <mesh name="Part__Feature010" file="Part__Feature010.stl" scale="0.001 0.001 0.001" />
    <material name="Part__Feature010" rgba="0.6274510025978088 0.6274510025978088 0.6274510025978088 1.0" shininess="0.8999999761581421" />
    <mesh name="Compound007" file="Compound007.stl" scale="0.001 0.001 0.001" />
    <material name="Compound007" rgba="0.3450980484485626 0.3686274588108063 0.8235294222831726 1.0" shininess="0.8999999761581421" />
    <mesh name="Solid004" file="Solid004.stl" scale="0.001 0.001 0.001" />
    <material name="Solid004" rgba="1.0 1.0 1.0 1.0" shininess="0.8999999761581421" />
    <mesh name="Part__Feature011" file="Part__Feature011.stl" scale="0.001 0.001 0.001" />
    <material name="Part__Feature011" rgba="1.0 1.0 1.0 1.0" shininess="0.8999999761581421" />
    <mesh name="Compound008" file="Compound008.stl" scale="0.001 0.001 0.001" />
    <material name="Compound008" rgba="0.3450980484485626 0.3686274588108063 0.8235294222831726 1.0" shininess="0.8999999761581421" />
    <mesh name="Solid005" file="Solid005.stl" scale="0.001 0.001 0.001" />
    <material name="Solid005" rgba="1.0 1.0 1.0 1.0" shininess="0.8999999761581421" />
    <mesh name="Part__Feature012" file="Part__Feature012.stl" scale="0.001 0.001 0.001" />
    <material name="Part__Feature012" rgba="1.0 1.0 1.0 1.0" shininess="0.8999999761581421" />
    <mesh name="Compound009" file="Compound009.stl" scale="0.001 0.001 0.001" />
    <material name="Compound009" rgba="0.3450980484485626 0.3686274588108063 0.8235294222831726 1.0" shininess="0.8999999761581421" />
    <mesh name="Solid006" file="Solid006.stl" scale="0.001 0.001 0.001" />
    <material name="Solid006" rgba="1.0 1.0 1.0 1.0" shininess="0.8999999761581421" />
    <mesh name="Part__Feature013" file="Part__Feature013.stl" scale="0.001 0.001 0.001" />
    <material name="Part__Feature013" rgba="1.0 1.0 1.0 1.0" shininess="0.8999999761581421" />
    <mesh name="Compound010" file="Compound010.stl" scale="0.001 0.001 0.001" />
    <material name="Compound010" rgba="0.3450980484485626 0.3686274588108063 0.8235294222831726 1.0" shininess="0.8999999761581421" />
    <mesh name="Solid008" file="Solid008.stl" scale="0.001 0.001 0.001" />
    <material name="Solid008" rgba="1.0 1.0 1.0 1.0" shininess="0.8999999761581421" />
    <mesh name="Part__Feature014" file="Part__Feature014.stl" scale="0.001 0.001 0.001" />
    <material name="Part__Feature014" rgba="1.0 1.0 1.0 1.0" shininess="0.8999999761581421" />
    <mesh name="Compound011" file="Compound011.stl" scale="0.001 0.001 0.001" />
    <material name="Compound011" rgba="0.3450980484485626 0.3686274588108063 0.8235294222831726 1.0" shininess="0.8999999761581421" />
    <mesh name="Solid009" file="Solid009.stl" scale="0.001 0.001 0.001" />
    <material name="Solid009" rgba="1.0 1.0 1.0 1.0" shininess="0.8999999761581421" />
    <mesh name="Part__Feature015" file="Part__Feature015.stl" scale="0.001 0.001 0.001" />
    <material name="Part__Feature015" rgba="1.0 1.0 1.0 1.0" shininess="0.8999999761581421" />
    <mesh name="Compound012" file="Compound012.stl" scale="0.001 0.001 0.001" />
    <material name="Compound012" rgba="0.3450980484485626 0.3686274588108063 0.8235294222831726 1.0" shininess="0.8999999761581421" />
    <mesh name="Solid010" file="Solid010.stl" scale="0.001 0.001 0.001" />
    <material name="Solid010" rgba="1.0 1.0 1.0 1.0" shininess="0.8999999761581421" />
    <mesh name="Part__Feature016" file="Part__Feature016.stl" scale="0.001 0.001 0.001" />
    <material name="Part__Feature016" rgba="1.0 1.0 1.0 1.0" shininess="0.8999999761581421" />
    <mesh name="Compound013" file="Compound013.stl" scale="0.001 0.001 0.001" />
    <material name="Compound013" rgba="0.3450980484485626 0.3686274588108063 0.8235294222831726 1.0" shininess="0.8999999761581421" />
    <mesh name="Solid011" file="Solid011.stl" scale="0.001 0.001 0.001" />
    <material name="Solid011" rgba="1.0 1.0 1.0 1.0" shininess="0.8999999761581421" />
    <mesh name="Part__Feature017" file="Part__Feature017.stl" scale="0.001 0.001 0.001" />
    <material name="Part__Feature017" rgba="1.0 1.0 1.0 1.0" shininess="0.8999999761581421" />
    <mesh name="Compound014" file="Compound014.stl" scale="0.001 0.001 0.001" />
    <material name="Compound014" rgba="0.3450980484485626 0.3686274588108063 0.8235294222831726 1.0" shininess="0.8999999761581421" />
    <mesh name="Solid012" file="Solid012.stl" scale="0.001 0.001 0.001" />
    <material name="Solid012" rgba="1.0 1.0 1.0 1.0" shininess="0.8999999761581421" />
    <mesh name="Part__Feature018" file="Part__Feature018.stl" scale="0.001 0.001 0.001" />
    <material name="Part__Feature018" rgba="1.0 1.0 1.0 1.0" shininess="0.8999999761581421" />
    <mesh name="Compound015" file="Compound015.stl" scale="0.001 0.001 0.001" />
    <material name="Compound015" rgba="0.3450980484485626 0.3686274588108063 0.8235294222831726 1.0" shininess="0.8999999761581421" />
    <mesh name="Solid013" file="Solid013.stl" scale="0.001 0.001 0.001" />
    <material name="Solid013" rgba="1.0 1.0 1.0 1.0" shininess="0.8999999761581421" />
    <mesh name="Solid014" file="Solid014.stl" scale="0.001 0.001 0.001" />
    <material name="Solid014" rgba="1.0 1.0 1.0 1.0" shininess="0.8999999761581421" />
    <mesh name="Part__Feature019" file="Part__Feature019.stl" scale="0.001 0.001 0.001" />
    <material name="Part__Feature019" rgba="1.0 1.0 1.0 1.0" shininess="0.8999999761581421" />
    <mesh name="Compound016" file="Compound016.stl" scale="0.001 0.001 0.001" />
    <material name="Compound016" rgba="0.3450980484485626 0.3686274588108063 0.8235294222831726 1.0" shininess="0.8999999761581421" />
    <mesh name="Part__Feature020" file="Part__Feature020.stl" scale="0.001 0.001 0.001" />
    <material name="Part__Feature020" rgba="1.0 1.0 1.0 1.0" shininess="0.8999999761581421" />
    <mesh name="Compound017" file="Compound017.stl" scale="0.001 0.001 0.001" />
    <material name="Compound017" rgba="0.3450980484485626 0.3686274588108063 0.8235294222831726 1.0" shininess="0.8999999761581421" />
    <mesh name="Solid015" file="Solid015.stl" scale="0.001 0.001 0.001" />
    <material name="Solid015" rgba="1.0 1.0 1.0 1.0" shininess="0.8999999761581421" />
    <mesh name="Part__Feature021" file="Part__Feature021.stl" scale="0.001 0.001 0.001" />
    <material name="Part__Feature021" rgba="1.0 1.0 1.0 1.0" shininess="0.8999999761581421" />
    <mesh name="Compound018" file="Compound018.stl" scale="0.001 0.001 0.001" />
    <material name="Compound018" rgba="0.3450980484485626 0.3686274588108063 0.8235294222831726 1.0" shininess="0.8999999761581421" />
    <mesh name="Solid016" file="Solid016.stl" scale="0.001 0.001 0.001" />
    <material name="Solid016" rgba="1.0 1.0 1.0 1.0" shininess="0.8999999761581421" />
    <mesh name="Part__Feature022" file="Part__Feature022.stl" scale="0.001 0.001 0.001" />
    <material name="Part__Feature022" rgba="1.0 1.0 1.0 1.0" shininess="0.8999999761581421" />
    <mesh name="Part__Feature023" file="Part__Feature023.stl" scale="0.001 0.001 0.001" />
    <material name="Part__Feature023" rgba="0.6274510025978088 0.6274510025978088 0.6274510025978088 1.0" shininess="0.8999999761581421" />
    <mesh name="Part__Feature024" file="Part__Feature024.stl" scale="0.001 0.001 0.001" />
    <material name="Part__Feature024" rgba="0.6274510025978088 0.6274510025978088 0.6274510025978088 1.0" shininess="0.8999999761581421" />
    <mesh name="Part__Feature025" file="Part__Feature025.stl" scale="0.001 0.001 0.001" />
    <material name="Part__Feature025" rgba="0.6274510025978088 0.6274510025978088 0.6274510025978088 1.0" shininess="0.8999999761581421" />
    <mesh name="Part__Feature026" file="Part__Feature026.stl" scale="0.001 0.001 0.001" />
    <material name="Part__Feature026" rgba="0.6274510025978088 0.6274510025978088 0.6274510025978088 1.0" shininess="0.8999999761581421" />
    <mesh name="Part__Feature027" file="Part__Feature027.stl" scale="0.001 0.001 0.001" />
    <material name="Part__Feature027" rgba="1.0 1.0 1.0 1.0" shininess="0.8999999761581421" />
    <mesh name="Part__Feature028" file="Part__Feature028.stl" scale="0.001 0.001 0.001" />
    <material name="Part__Feature028" rgba="1.0 1.0 1.0 1.0" shininess="0.8999999761581421" />
  </asset>
  <worldbody>
    <!--Lighting and floor-->
    <light diffuse=".8 .8 .8" pos="0 0 4" dir="0 0 -1" />
    <light diffuse=".6 .6 .6" pos="4 4 4" dir="-1 -1 -1" />
    <!--Part Meshes-->
    <geom name="floor" pos="0 0 -0.01528462486233359" size="0 0 1" type="plane" material="groundplane" />
    <!--Assembly-->
    <body name="Compound" pos="0 0 0" quat="1.0 0.0 0.0 0.0">
      <geom type="mesh" name="Compound geom" mesh="Compound" material="Compound" contype="0" conaffinity="0" />
      <body name="Compound001" pos="0 0 0" quat="1.0 0.0 0.0 0.0">
        <geom type="mesh" name="Compound001 geom" mesh="Compound001" material="Compound001" contype="0" conaffinity="0" />
        <body name="Solid" pos="0 0 0" quat="1.0 0.0 0.0 0.0">
          <geom type="mesh" name="Solid geom" mesh="Solid" material="Solid" contype="0" conaffinity="0" />
        </body>
        <body name="Part__Feature" pos="0 0 0" quat="1.0 0.0 0.0 0.0">
          <geom type="mesh" name="Part__Feature geom" mesh="Part__Feature" material="Part__Feature" contype="0" conaffinity="0" />
          <body name="Compound002" pos="0 0 0" quat="1.0 0.0 0.0 0.0">
            <geom type="mesh" name="Compound002 geom" mesh="Compound002" material="Compound002" contype="0" conaffinity="0" />
            <body name="Part__Feature003" pos="0 0 0" quat="1.0 0.0 0.0 0.0">
              <geom type="mesh" name="Part__Feature003 geom" mesh="Part__Feature003" material="Part__Feature003" contype="0" conaffinity="0" />
            </body>
            <body name="Part__Feature004" pos="0 0 0" quat="1.0 0.0 0.0 0.0">
              <geom type="mesh" name="Part__Feature004 geom" mesh="Part__Feature004" material="Part__Feature004" contype="0" conaffinity="0" />
              <body name="Compound003" pos="0 0 0" quat="1.0 0.0 0.0 0.0">
                <geom type="mesh" name="Compound003 geom" mesh="Compound003" material="Compound003" contype="0" conaffinity="0" />
                <body name="Solid001" pos="0 0 0" quat="1.0 0.0 0.0 0.0">
                  <geom type="mesh" name="Solid001 geom" mesh="Solid001" material="Solid001" contype="0" conaffinity="0" />
                </body>
                <body name="Part__Feature005" pos="0 0 0" quat="1.0 0.0 0.0 0.0">
                  <geom type="mesh" name="Part__Feature005 geom" mesh="Part__Feature005" material="Part__Feature005" contype="0" conaffinity="0" />
                  <body name="Part__Feature006" pos="0 0 0" quat="1.0 0.0 0.0 0.0">
                    <geom type="mesh" name="Part__Feature006 geom" mesh="Part__Feature006" material="Part__Feature006" contype="0" conaffinity="0" />
                  </body>
                </body>
                <joint type="hinge" name="Revolute002" pos="0.022370026219401994 0.031012283464067862 0.07694119331606378" axis="-0.9563412316668666 0.28710772052817757 0.05459492125659976" />
              </body>
            </body>
            <joint type="hinge" name="Revolute001" pos="0.019688740755565006 0.03415521719034734 0.034325793800705086" axis="-0.956341231666867 0.2871077205281774 0.05459492125659994" />
          </body>
        </body>
        <joint type="hinge" name="Revolute" pos="0.021669007652103806 -0.014010170976901572 0.04316298372266052" axis="-0.004768051882588358 -0.20211048929575764 0.9793511197715938" />
      </body>
      <body name="Compound004" pos="0 0 0" quat="1.0 0.0 0.0 0.0">
        <geom type="mesh" name="Compound004 geom" mesh="Compound004" material="Compound004" contype="0" conaffinity="0" />
        <body name="Solid002" pos="0 0 0" quat="1.0 0.0 0.0 0.0">
          <geom type="mesh" name="Solid002 geom" mesh="Solid002" material="Solid002" contype="0" conaffinity="0" />
        </body>
        <body name="Part__Feature007" pos="0 0 0" quat="1.0 0.0 0.0 0.0">
          <geom type="mesh" name="Part__Feature007 geom" mesh="Part__Feature007" material="Part__Feature007" contype="0" conaffinity="0" />
          <body name="Compound005" pos="0 0 0" quat="1.0 0.0 0.0 0.0">
            <geom type="mesh" name="Compound005 geom" mesh="Compound005" material="Compound005" contype="0" conaffinity="0" />
            <body name="Solid003" pos="0 0 0" quat="1.0 0.0 0.0 0.0">
              <geom type="mesh" name="Solid003 geom" mesh="Solid003" material="Solid003" contype="0" conaffinity="0" />
            </body>
            <body name="Part__Feature008" pos="0 0 0" quat="1.0 0.0 0.0 0.0">
              <geom type="mesh" name="Part__Feature008 geom" mesh="Part__Feature008" material="Part__Feature008" contype="0" conaffinity="0" />
              <body name="Compound006" pos="0 0 0" quat="1.0 0.0 0.0 0.0">
                <geom type="mesh" name="Compound006 geom" mesh="Compound006" material="Compound006" contype="0" conaffinity="0" />
                <body name="Part__Feature009" pos="0 0 0" quat="1.0 0.0 0.0 0.0">
                  <geom type="mesh" name="Part__Feature009 geom" mesh="Part__Feature009" material="Part__Feature009" contype="0" conaffinity="0" />
                  <body name="Part__Feature010" pos="0 0 0" quat="1.0 0.0 0.0 0.0">
                    <geom type="mesh" name="Part__Feature010 geom" mesh="Part__Feature010" material="Part__Feature010" contype="0" conaffinity="0" />
                  </body>
                </body>
                <body name="Solid014" pos="0 0 0" quat="1.0 0.0 0.0 0.0">
                  <geom type="mesh" name="Solid014 geom" mesh="Solid014" material="Solid014" contype="0" conaffinity="0" />
                </body>
                <joint type="hinge" name="Revolute005" pos="-0.020518617529664693 -0.12707008443856538 0.03476432536182847" axis="0.7167420904680235 -0.6836293775835769 -0.1375923321127283" />
              </body>
            </body>
            <body name="Part__Feature028" pos="0 0 0" quat="1.0 0.0 0.0 0.0">
              <geom type="mesh" name="Part__Feature028 geom" mesh="Part__Feature028" material="Part__Feature028" contype="0" conaffinity="0" />
            </body>
            <joint type="hinge" name="Revolute004" pos="-0.0016001089697122346 -0.1028956288332402 0.004917628223733493" axis="0.7167420904680231 -0.6836293775835771 -0.13759233211272742" />
          </body>
        </body>
        <joint type="hinge" name="Revolute003" pos="0.017244024622226815 -0.06577264093294014 0.02939587159459921" axis="0.004768051882588392 0.20211048929575767 -0.9793511197715941" />
      </body>
      <body name="Compound007" pos="0 0 0" quat="1.0 0.0 0.0 0.0">
        <geom type="mesh" name="Compound007 geom" mesh="Compound007" material="Compound007" contype="0" conaffinity="0" />
        <body name="Solid004" pos="0 0 0" quat="1.0 0.0 0.0 0.0">
          <geom type="mesh" name="Solid004 geom" mesh="Solid004" material="Solid004" contype="0" conaffinity="0" />
        </body>
        <body name="Part__Feature011" pos="0 0 0" quat="1.0 0.0 0.0 0.0">
          <geom type="mesh" name="Part__Feature011 geom" mesh="Part__Feature011" material="Part__Feature011" contype="0" conaffinity="0" />
          <body name="Compound008" pos="0 0 0" quat="1.0 0.0 0.0 0.0">
            <geom type="mesh" name="Compound008 geom" mesh="Compound008" material="Compound008" contype="0" conaffinity="0" />
            <body name="Solid005" pos="0 0 0" quat="1.0 0.0 0.0 0.0">
              <geom type="mesh" name="Solid005 geom" mesh="Solid005" material="Solid005" contype="0" conaffinity="0" />
            </body>
            <body name="Part__Feature012" pos="0 0 0" quat="1.0 0.0 0.0 0.0">
              <geom type="mesh" name="Part__Feature012 geom" mesh="Part__Feature012" material="Part__Feature012" contype="0" conaffinity="0" />
              <body name="Compound009" pos="0 0 0" quat="1.0 0.0 0.0 0.0">
                <geom type="mesh" name="Compound009 geom" mesh="Compound009" material="Compound009" contype="0" conaffinity="0" />
                <body name="Solid006" pos="0 0 0" quat="1.0 0.0 0.0 0.0">
                  <geom type="mesh" name="Solid006 geom" mesh="Solid006" material="Solid006" contype="0" conaffinity="0" />
                </body>
                <body name="Part__Feature013" pos="0 0 0" quat="1.0 0.0 0.0 0.0">
                  <geom type="mesh" name="Part__Feature013 geom" mesh="Part__Feature013" material="Part__Feature013" contype="0" conaffinity="0" />
                  <body name="Part__Feature025" pos="0 0 0" quat="1.0 0.0 0.0 0.0">
                    <geom type="mesh" name="Part__Feature025 geom" mesh="Part__Feature025" material="Part__Feature025" contype="0" conaffinity="0" />
                  </body>
                </body>
                <joint type="hinge" name="Revolute008" pos="0.06309686698627572 0.06836539163590695 0.047819800562966475" axis="-0.9978083728613792 0.06559812480556398 0.00867969295081239" />
              </body>
            </body>
            <joint type="hinge" name="Revolute007" pos="0.059207555249631186 0.028629895119875504 0.03235683930583162" axis="-0.9978083728613796 0.06559812480556453 0.008679692950812473" />
          </body>
        </body>
        <joint type="hinge" name="Revolute006" pos="0.07151134601218004 -0.017502982012692053 0.03962157469969464" axis="-0.004768051882588384 -0.2021104892957577 0.979351119771594" />
      </body>
      <body name="Compound010" pos="0 0 0" quat="1.0 0.0 0.0 0.0">
        <geom type="mesh" name="Compound010 geom" mesh="Compound010" material="Compound010" contype="0" conaffinity="0" />
        <body name="Solid008" pos="0 0 0" quat="1.0 0.0 0.0 0.0">
          <geom type="mesh" name="Solid008 geom" mesh="Solid008" material="Solid008" contype="0" conaffinity="0" />
        </body>
        <body name="Part__Feature014" pos="0 0 0" quat="1.0 0.0 0.0 0.0">
          <geom type="mesh" name="Part__Feature014 geom" mesh="Part__Feature014" material="Part__Feature014" contype="0" conaffinity="0" />
          <body name="Compound011" pos="0 0 0" quat="1.0 0.0 0.0 0.0">
            <geom type="mesh" name="Compound011 geom" mesh="Compound011" material="Compound011" contype="0" conaffinity="0" />
            <body name="Solid009" pos="0 0 0" quat="1.0 0.0 0.0 0.0">
              <geom type="mesh" name="Solid009 geom" mesh="Solid009" material="Solid009" contype="0" conaffinity="0" />
            </body>
            <body name="Part__Feature015" pos="0 0 0" quat="1.0 0.0 0.0 0.0">
              <geom type="mesh" name="Part__Feature015 geom" mesh="Part__Feature015" material="Part__Feature015" contype="0" conaffinity="0" />
              <body name="Compound012" pos="0 0 0" quat="1.0 0.0 0.0 0.0">
                <geom type="mesh" name="Compound012 geom" mesh="Compound012" material="Compound012" contype="0" conaffinity="0" />
                <body name="Solid010" pos="0 0 0" quat="1.0 0.0 0.0 0.0">
                  <geom type="mesh" name="Solid010 geom" mesh="Solid010" material="Solid010" contype="0" conaffinity="0" />
                </body>
                <body name="Part__Feature016" pos="0 0 0" quat="1.0 0.0 0.0 0.0">
                  <geom type="mesh" name="Part__Feature016 geom" mesh="Part__Feature016" material="Part__Feature016" contype="0" conaffinity="0" />
                  <body name="Part__Feature026" pos="0 0 0" quat="1.0 0.0 0.0 0.0">
                    <geom type="mesh" name="Part__Feature026 geom" mesh="Part__Feature026" material="Part__Feature026" contype="0" conaffinity="0" />
                  </body>
                </body>
                <joint type="hinge" name="Revolute012" pos="0.18828007195887442 0.03437640266364251 0.018073225848690807" axis="-0.46104017651857876 0.8695073888321556 0.17719722458888715" />
              </body>
            </body>
            <joint type="hinge" name="Revolute011" pos="0.15237051279040464 0.014248641924215788 0.02984252523066577" axis="-0.4610401765185787 0.8695073888321556 0.17719722458888665" />
          </body>
        </body>
        <joint type="hinge" name="Revolute010" pos="0.12133938021660812 -0.021602124516369777 0.03901821903604353" axis="-0.004768051882588399 -0.20211048929575764 0.9793511197715937" />
      </body>
      <body name="Compound013" pos="0 0 0" quat="1.0 0.0 0.0 0.0">
        <geom type="mesh" name="Compound013 geom" mesh="Compound013" material="Compound013" contype="0" conaffinity="0" />
        <body name="Solid011" pos="0 0 0" quat="1.0 0.0 0.0 0.0">
          <geom type="mesh" name="Solid011 geom" mesh="Solid011" material="Solid011" contype="0" conaffinity="0" />
        </body>
        <body name="Part__Feature017" pos="0 0 0" quat="1.0 0.0 0.0 0.0">
          <geom type="mesh" name="Part__Feature017 geom" mesh="Part__Feature017" material="Part__Feature017" contype="0" conaffinity="0" />
          <body name="Compound014" pos="0 0 0" quat="1.0 0.0 0.0 0.0">
            <geom type="mesh" name="Compound014 geom" mesh="Compound014" material="Compound014" contype="0" conaffinity="0" />
            <body name="Solid012" pos="0 0 0" quat="1.0 0.0 0.0 0.0">
              <geom type="mesh" name="Solid012 geom" mesh="Solid012" material="Solid012" contype="0" conaffinity="0" />
            </body>
            <body name="Part__Feature018" pos="0 0 0" quat="1.0 0.0 0.0 0.0">
              <geom type="mesh" name="Part__Feature018 geom" mesh="Part__Feature018" material="Part__Feature018" contype="0" conaffinity="0" />
              <body name="Compound015" pos="0 0 0" quat="1.0 0.0 0.0 0.0">
                <geom type="mesh" name="Compound015 geom" mesh="Compound015" material="Compound015" contype="0" conaffinity="0" />
                <body name="Solid013" pos="0 0 0" quat="1.0 0.0 0.0 0.0">
                  <geom type="mesh" name="Solid013 geom" mesh="Solid013" material="Solid013" contype="0" conaffinity="0" />
                </body>
                <body name="Part__Feature019" pos="0 0 0" quat="1.0 0.0 0.0 0.0">
                  <geom type="mesh" name="Part__Feature019 geom" mesh="Part__Feature019" material="Part__Feature019" contype="0" conaffinity="0" />
                  <body name="Part__Feature023" pos="0 0 0" quat="1.0 0.0 0.0 0.0">
                    <geom type="mesh" name="Part__Feature023 geom" mesh="Part__Feature023" material="Part__Feature023" contype="0" conaffinity="0" />
                  </body>
                </body>
                <joint type="hinge" name="Revolute015" pos="0.06384585324557952 -0.1462932499911243 -0.016957354146289193" axis="0.9783636705980744 -0.2035140871469756 -0.03723633154052947" />
              </body>
            </body>
            <joint type="hinge" name="Revolute014" pos="0.07320777247694321 -0.1106644840058414 0.00367856366788641" axis="0.9783636705980749 -0.20351408714697217 -0.03723633154052816" />
          </body>
        </body>
        <joint type="hinge" name="Revolute013" pos="0.06707205882665528 -0.06987178343661787 0.0287925159309481" axis="-0.004768051882588362 -0.20211048929575762 0.9793511197715936" />
      </body>
      <body name="Compound016" pos="0 0 0" quat="1.0 0.0 0.0 0.0">
        <geom type="mesh" name="Compound016 geom" mesh="Compound016" material="Compound016" contype="0" conaffinity="0" />
        <body name="Part__Feature020" pos="0 0 0" quat="1.0 0.0 0.0 0.0">
          <geom type="mesh" name="Part__Feature020 geom" mesh="Part__Feature020" material="Part__Feature020" contype="0" conaffinity="0" />
          <body name="Compound017" pos="0 0 0" quat="1.0 0.0 0.0 0.0">
            <geom type="mesh" name="Compound017 geom" mesh="Compound017" material="Compound017" contype="0" conaffinity="0" />
            <body name="Solid015" pos="0 0 0" quat="1.0 0.0 0.0 0.0">
              <geom type="mesh" name="Solid015 geom" mesh="Solid015" material="Solid015" contype="0" conaffinity="0" />
            </body>
            <body name="Part__Feature021" pos="0 0 0" quat="1.0 0.0 0.0 0.0">
              <geom type="mesh" name="Part__Feature021 geom" mesh="Part__Feature021" material="Part__Feature021" contype="0" conaffinity="0" />
              <body name="Compound018" pos="0 0 0" quat="1.0 0.0 0.0 0.0">
                <geom type="mesh" name="Compound018 geom" mesh="Compound018" material="Compound018" contype="0" conaffinity="0" />
                <body name="Solid016" pos="0 0 0" quat="1.0 0.0 0.0 0.0">
                  <geom type="mesh" name="Solid016 geom" mesh="Solid016" material="Solid016" contype="0" conaffinity="0" />
                </body>
                <body name="Part__Feature022" pos="0 0 0" quat="1.0 0.0 0.0 0.0">
                  <geom type="mesh" name="Part__Feature022 geom" mesh="Part__Feature022" material="Part__Feature022" contype="0" conaffinity="0" />
                  <body name="Part__Feature024" pos="0 0 0" quat="1.0 0.0 0.0 0.0">
                    <geom type="mesh" name="Part__Feature024 geom" mesh="Part__Feature024" material="Part__Feature024" contype="0" conaffinity="0" />
                  </body>
                </body>
                <joint type="hinge" name="Revolute018" pos="0.13975356752487558 -0.15335316107157454 0.007465694170866819" axis="0.9944561333227823 0.10191905081095831 0.025874813593426957" />
              </body>
            </body>
            <joint type="hinge" name="Revolute017" pos="0.1366295930054685 -0.11079624007927827 0.003960147300896912" axis="0.9944561333227816 0.10191905081096207 0.025874813593426527" />
          </body>
        </body>
        <joint type="hinge" name="Revolute016" pos="0.11690009303108334 -0.07397092594029563 0.02818916026729701" axis="-0.004768051882588389 -0.20211048929575767 0.9793511197715938" />
      </body>
      <body name="Part__Feature027" pos="0 0 0" quat="1.0 0.0 0.0 0.0">
        <geom type="mesh" name="Part__Feature027 geom" mesh="Part__Feature027" material="Part__Feature027" contype="0" conaffinity="0" />
      </body>
    </body>
  </worldbody>
  <contact />
  <equality />
  <tendon />
  <actuator>
    <position name="Revolute002" joint="Revolute002" kp="100" />
    <position name="Revolute001" joint="Revolute001" kp="100" />
    <position name="Revolute" joint="Revolute" kp="100" />
    <position name="Revolute005" joint="Revolute005" kp="100" />
    <position name="Revolute004" joint="Revolute004" kp="100" />
    <position name="Revolute003" joint="Revolute003" kp="100" />
    <position name="Revolute008" joint="Revolute008" kp="100" />
    <position name="Revolute007" joint="Revolute007" kp="100" />
    <position name="Revolute006" joint="Revolute006" kp="100" />
    <position name="Revolute012" joint="Revolute012" kp="100" />
    <position name="Revolute011" joint="Revolute011" kp="100" />
    <position name="Revolute010" joint="Revolute010" kp="100" />
    <position name="Revolute015" joint="Revolute015" kp="100" />
    <position name="Revolute014" joint="Revolute014" kp="100" />
    <position name="Revolute013" joint="Revolute013" kp="100" />
    <position name="Revolute018" joint="Revolute018" kp="100" />
    <position name="Revolute017" joint="Revolute017" kp="100" />
    <position name="Revolute016" joint="Revolute016" kp="100" />
  </actuator>
  <sensor>
    <jointpos name="Revolute002_pos" joint="Revolute002" />
    <jointpos name="Revolute001_pos" joint="Revolute001" />
    <jointpos name="Revolute_pos" joint="Revolute" />
    <jointpos name="Revolute005_pos" joint="Revolute005" />
    <jointpos name="Revolute004_pos" joint="Revolute004" />
    <jointpos name="Revolute003_pos" joint="Revolute003" />
    <jointpos name="Revolute008_pos" joint="Revolute008" />
    <jointpos name="Revolute007_pos" joint="Revolute007" />
    <jointpos name="Revolute006_pos" joint="Revolute006" />
    <jointpos name="Revolute012_pos" joint="Revolute012" />
    <jointpos name="Revolute011_pos" joint="Revolute011" />
    <jointpos name="Revolute010_pos" joint="Revolute010" />
    <jointpos name="Revolute015_pos" joint="Revolute015" />
    <jointpos name="Revolute014_pos" joint="Revolute014" />
    <jointpos name="Revolute013_pos" joint="Revolute013" />
    <jointpos name="Revolute018_pos" joint="Revolute018" />
    <jointpos name="Revolute017_pos" joint="Revolute017" />
    <jointpos name="Revolute016_pos" joint="Revolute016" />
  </sensor>
</mujoco>